<?xml version="1.0" ?>
<!-- =================================================================================== -->
<!-- |    This document was autogenerated by xacro from uibk_robot.urdf.xacro          | -->
<!-- |    EDITING THIS FILE BY HAND IS NOT RECOMMENDED                                 | -->
<!-- =================================================================================== -->
<robot name="Eddie" xmlns:controller="http://playerstage.sourceforge.net/gazebo/xmlschema/#controller" xmlns:interface="http://playerstage.sourceforge.net/gazebo/xmlschema/#interface" xmlns:sensor="http://playerstage.sourceforge.net/gazebo/xmlschema/#sensor" xmlns:xacro="http://www.ros.org/wiki/xacro">
  <material name="DarkGrey">
    <color rgba="0.3 0.3 0.3 1.0"/>
  </material>
  <material name="LightGrey">
    <color rgba="0.8 0.8 0.8 1.0"/>
  </material>
  <material name="Red">
    <color rgba="0.3 0.3 0.3 1.0"/>
  </material>
  <material name="Black">
    <color rgba="0 0 0 1.0"/>
  </material>
  <material name="Orange">
    <color rgba="1.0 0.487 0 1.0"/>
  </material>
  <material name="Silver">
    <color rgba="1.0 1.0 1.0 1.0"/>
  </material>
  <material name="Grey">
    <color rgba="0.7 0.7 0.7 1.0"/>
  </material>
  <material name="Blue">
    <color rgba="0.0 0.0 0.8 1.0"/>
  </material>
  <material name="HandGray">
    <color rgba="0.953 0.996 0.694 1.0"/>
  </material>
  <material name="SickBlue">
    <color rgba="0.3058 0.5921 0.7294 1.0"/>
  </material>
  <material name="Schunk/LightGrey">
    <color rgba="0.7 0.7 0.7 1.0"/>
  </material>
  <material name="Schunk/DarkGrey">
    <color rgba="0.4 0.4 0.4 1.0"/>
  </material>
  <material name="Schunk/Black">
    <color rgba="0.0 0.0 0.0 1.0"/>
  </material>
  <material name="Schunk/DarkGolden">
    <color rgba="0.4 0.4 0.3 1.0"/>
  </material>
  <material name="Schunk/Blue">
    <color rgba="0.0 0.0 0.8 1.0"/>
  </material>
  <material name="KIT/White">
    <color rgba="1 1 1 1.0"/>
  </material>
  <material name="KIT/DarkGrey">
    <color rgba="0.3 0.3 0.3 1.0"/>
  </material>
  <material name="KIT/LightGrey">
    <color rgba="0.8 0.8 0.8 1.0"/>
  </material>
  <material name="KIT/Red">
    <color rgba="0.3 0.3 0.3 1.0"/>
  </material>
  <material name="KIT/Black">
    <color rgba="0 0 0 1.0"/>
  </material>
  <material name="KIT/Orange">
    <color rgba="1.0 0.487 0 1.0"/>
  </material>
  <material name="KIT/Silver">
    <color rgba="1.0 1.0 1.0 1.0"/>
  </material>
  <material name="KIT/Grey">
    <color rgba="0.7 0.7 0.7 1.0"/>
  </material>
  <material name="KIT/Blue">
    <color rgba="0.0 0.0 0.8 1.0"/>
  </material>
  <material name="KIT/HandGray">
    <color rgba="0.953 0.996 0.694 1.0"/>
  </material>
  <material name="KIT/SickBlue">
    <color rgba="0.3058 0.5921 0.7294 1.0"/>
  </material>
  <link name="world_link"/>
  <joint name="world_table_base_joint" type="fixed">
    <origin rpy="0 0 1.5708" xyz="-0.42 -0.3 0.08"/>
    <parent link="world_link"/>
    <child link="table_plate_link"/>
  </joint>
  <link name="table_plate_link">
    <visual>
      <origin xyz="1.0 -0.6 -0.055"/>
      <geometry>
        <box size="2.0 1.2 0.11"/>
      </geometry>
      <material name="LightGrey"/>
    </visual>
    <collision>
      <origin xyz="1.0 -0.6 -0.055"/>
      <geometry>
        <box size="2.0 1.2 0.11"/>
      </geometry>
    </collision>
  </link>
  <joint name="leg_0_joint" type="fixed">
    <origin xyz="0.055 -0.055 -0.455"/>
    <parent link="table_plate_link"/>
    <child link="leg_0_link"/>
  </joint>
  <link name="leg_0_link">
    <visual>
      <geometry>
        <box size="0.03 -0.03 0.69"/>
      </geometry>
      <material name="Black"/>
    </visual>
    <collision>
      <geometry>
        <box size="0.03 -0.03 0.69"/>
      </geometry>
    </collision>
  </link>
  <joint name="leg_1_joint" type="fixed">
    <origin xyz="1.945 -0.055 -0.455"/>
    <parent link="table_plate_link"/>
    <child link="leg_1_link"/>
  </joint>
  <link name="leg_1_link">
    <visual>
      <geometry>
        <box size="0.03 -0.03 0.69"/>
      </geometry>
      <material name="Black"/>
    </visual>
    <collision>
      <geometry>
        <box size="0.03 -0.03 0.69"/>
      </geometry>
    </collision>
  </link>
  <joint name="leg_2_joint" type="fixed">
    <origin xyz="0.055 -1.145 -0.455"/>
    <parent link="table_plate_link"/>
    <child link="leg_2_link"/>
  </joint>
  <link name="leg_2_link">
    <visual>
      <geometry>
        <box size="0.03 -0.03 0.69"/>
      </geometry>
      <material name="Black"/>
    </visual>
    <collision>
      <geometry>
        <box size="0.03 -0.03 0.69"/>
      </geometry>
    </collision>
  </link>
  <joint name="leg_3_joint" type="fixed">
    <origin xyz="1.945 -1.145 -0.455"/>
    <parent link="table_plate_link"/>
    <child link="leg_3_link"/>
  </joint>
  <link name="leg_3_link">
    <visual>
      <geometry>
        <box size="0.03 -0.03 0.69"/>
      </geometry>
      <material name="Black"/>
    </visual>
    <collision>
      <geometry>
        <box size="0.03 -0.03 0.69"/>
      </geometry>
    </collision>
  </link>
  <joint name="world_torso_base_joint" type="fixed">
    <origin xyz="-0.4723 0.6767 -0.734"/>
    <parent link="world_link"/>
    <child link="torso_link"/>
  </joint>
  <link name="torso_link">
    <visual>
      <geometry>
        <mesh filename="package://torso_uibk/meshes/torso.stl"/>
      </geometry>
      <material name="Silver"/>
    </visual>
    <collision>
      <geometry>
        <mesh filename="package://torso_uibk/meshes/torso.stl"/>
      </geometry>
    </collision>
  </link>
  <joint name="world_left_arm_base_joint" type="fixed">
    <origin rpy="1.9485 -0.2114 2.6898" xyz="-0.4923 0.7541 0.6295"/>
    <parent link="world_link"/>
    <child link="calib_left_arm_base_link"/>
  </joint>
  <link name="calib_left_arm_base_link"/>
  <joint name="calib_left_arm_base_joint" type="fixed">
    <origin rpy="0 0 3.14159265359" xyz="0 0 0"/>
    <parent link="calib_left_arm_base_link"/>
    <child link="left_arm_base_link"/>
  </joint>
  <link name="left_arm_base_link">
    <inertial>
      <mass value="2.0"/>
      <origin xyz="0 0 0.055"/>
      <inertia ixx="0.00381666666667" ixy="0" ixz="0" iyy="0.0036" iyz="0" izz="0.00381666666667"/>
    </inertial>
    <visual>
      <origin rpy="0 0 0" xyz="0 0 0"/>
      <geometry>
        <mesh filename="package://lwr_description/meshes/lwr/base.STL"/>
      </geometry>
      <material name="Orange"/>
    </visual>
    <collision>
      <origin rpy="0 0 3.14159265359" xyz="0 0 0.055"/>
      <geometry>
        <!--          <mesh filename="package://lwr_description/meshes/lwr/convex/arm_base_convex.stl"/> -->
        <cylinder length="0.11" radius="0.07"/>
      </geometry>
    </collision>
  </link>
  <joint name="left_arm_0_joint" type="revolute">
    <origin rpy="0 0 0" xyz="0 0 0.11"/>
    <axis xyz="0 0 1"/>
    <limit effort="204" lower="-2.96705972839" upper="2.96705972839" velocity="0.0191986217719"/>
    <safety_controller k_position="30" k_velocity="30" soft_lower_limit="-2.93215314335" soft_upper_limit="2.93215314335"/>
    <dynamics damping="1.0"/>
    <parent link="left_arm_base_link"/>
    <child link="left_arm_1_link"/>
  </joint>
  <link name="left_arm_1_link">
    <inertial>
      <mass value="2.0"/>
      <origin rpy="0 0 0" xyz="0 -0.06 0.130"/>
      <inertia ixx="0.0136666666667" ixy="0" ixz="0" iyy="0.003" iyz="0" izz="0.0118666666667"/>
    </inertial>
    <visual>
      <origin rpy="0 0 0" xyz="0 0 -0.008"/>
      <geometry>
        <mesh filename="package://lwr_description/meshes/lwr/link_1.STL"/>
      </geometry>
      <material name="Orange"/>
    </visual>
    <!--
      <collision>
        <origin xyz="0 0 0" rpy="0 0 0"/>
        <geometry>
          <mesh filename="package://lwr_description/meshes/lwr/convex/arm_segment_a_convex.stl"/>
        </geometry>
      </collision>
 -->
    <collision>
      <origin rpy="0 0 0" xyz="0 0 0.0"/>
      <geometry>
        <sphere radius="0.07"/>
      </geometry>
    </collision>
    <collision>
      <origin rpy="0 0 0" xyz="0 -0.06 0.2"/>
      <geometry>
        <sphere radius="0.07"/>
      </geometry>
    </collision>
    <collision>
      <origin rpy="0.291 0 0" xyz="0 -0.03 0.1"/>
      <geometry>
        <cylinder length="0.208" radius="0.07"/>
      </geometry>
    </collision>
  </link>
  <gazebo reference="left_arm_1_link">
    <gravity>false</gravity>
  </gazebo>
  <transmission name="left_arm_0_trans" type="SimpleTransmission">
    <actuator name="left_arm_0_motor"/>
    <joint name="left_arm_0_joint"/>
    <mechanicalReduction>1.0</mechanicalReduction>
  </transmission>
  <joint name="left_arm_1_joint" type="revolute">
    <origin rpy="0 0 0" xyz="0 0 0.2005"/>
    <axis xyz="0 1 0"/>
    <limit effort="306" lower="-2.09439510239" upper="2.09439510239" velocity="0.0191986217719"/>
    <safety_controller k_position="30" k_velocity="30" soft_lower_limit="-2.05948851735" soft_upper_limit="2.05948851735"/>
    <dynamics damping="1.0" friction="10"/>
    <parent link="left_arm_1_link"/>
    <child link="left_arm_2_link"/>
  </joint>
  <link name="left_arm_2_link">
    <inertial>
      <mass value="2.0"/>
      <origin rpy="0 0 0" xyz="0 0.06 0.07"/>
      <inertia ixx="0.0136666666667" ixy="0" ixz="0" iyy="0.003" iyz="0" izz="0.0118666666667"/>
    </inertial>
    <visual>
      <origin rpy="0 0 0" xyz="0 0 0.0"/>
      <geometry>
        <mesh filename="package://lwr_description/meshes/lwr/link_2.STL"/>
      </geometry>
      <material name="Orange"/>
    </visual>
    <!--
      <collision>
        <origin xyz="0 0 0.2" rpy="${M_PI} 0 0"/>
        <geometry>
          <mesh filename="package://lwr_description/meshes/lwr/convex/arm_segment_b_convex.stl"/>
        </geometry>
      </collision>
-->
    <collision>
      <origin rpy="0 0 0" xyz="0 0 0.2"/>
      <geometry>
        <sphere radius="0.07"/>
      </geometry>
    </collision>
    <collision>
      <origin rpy="0 0 0" xyz="0 0.06 0.0"/>
      <geometry>
        <sphere radius="0.07"/>
      </geometry>
    </collision>
    <collision>
      <origin rpy="0.291 0 0" xyz="0 0.03 0.1"/>
      <geometry>
        <cylinder length="0.208" radius="0.07"/>
      </geometry>
    </collision>
  </link>
  <gazebo reference="left_arm_2_link">
    <gravity>false</gravity>
  </gazebo>
  <transmission name="left_arm_1_trans" type="SimpleTransmission">
    <actuator name="left_arm_1_motor"/>
    <joint name="left_arm_1_joint"/>
    <mechanicalReduction>1.0</mechanicalReduction>
  </transmission>
  <joint name="left_arm_2_joint" type="revolute">
    <origin rpy="0 0 0" xyz="0 0 0.20"/>
    <axis xyz="0 0 1"/>
    <limit effort="204" lower="-2.96705972839" upper="2.96705972839" velocity="0.0226892802759"/>
    <safety_controller k_position="30" k_velocity="30" soft_lower_limit="-2.93215314335" soft_upper_limit="2.93215314335"/>
    <dynamics damping="1.0"/>
    <parent link="left_arm_2_link"/>
    <child link="left_arm_3_link"/>
  </joint>
  <link name="left_arm_3_link">
    <inertial>
      <mass value="2.0"/>
      <origin rpy="0 0 0" xyz="0 0.06 0.130"/>
      <inertia ixx="0.0136666666667" ixy="0" ixz="0" iyy="0.003" iyz="0" izz="0.0118666666667"/>
    </inertial>
    <visual>
      <origin rpy="0 0 0" xyz="0 0 -0.008"/>
      <geometry>
        <mesh filename="package://lwr_description/meshes/lwr/link_3.STL"/>
      </geometry>
      <material name="Orange"/>
    </visual>
    <!--
      <collision>
        <origin xyz="0 0 0" rpy="0 0 ${M_PI}"/>
        <geometry>
          <mesh filename="package://lwr_description/meshes/lwr/convex/arm_segment_a_convex.stl"/>
        </geometry>
      </collision>
-->
    <collision>
      <origin rpy="0 0 0" xyz="0 0 0.0"/>
      <geometry>
        <sphere radius="0.07"/>
      </geometry>
    </collision>
    <collision>
      <origin rpy="0 0 0" xyz="0 0.06 0.2"/>
      <geometry>
        <sphere radius="0.07"/>
      </geometry>
    </collision>
    <collision>
      <origin rpy="-0.291 0 0" xyz="0 0.03 0.1"/>
      <geometry>
        <cylinder length="0.208" radius="0.07"/>
      </geometry>
    </collision>
  </link>
  <gazebo reference="left_arm_3_link">
    <gravity>false</gravity>
  </gazebo>
  <transmission name="left_arm_2_trans" type="SimpleTransmission">
    <actuator name="left_arm_2_motor"/>
    <joint name="left_arm_2_joint"/>
    <mechanicalReduction>1.0</mechanicalReduction>
  </transmission>
  <joint name="left_arm_3_joint" type="revolute">
    <origin rpy="0 0 0" xyz="0 0 0.20"/>
    <axis xyz="0 -1 0"/>
    <limit effort="306" lower="-2.09439510239" upper="2.09439510239" velocity="0.0226892802759"/>
    <safety_controller k_position="30" k_velocity="30" soft_lower_limit="-2.05948851735" soft_upper_limit="2.05948851735"/>
    <dynamics damping="1.0"/>
    <parent link="left_arm_3_link"/>
    <child link="left_arm_4_link"/>
  </joint>
  <link name="left_arm_4_link">
    <inertial>
      <mass value="2.0"/>
      <origin rpy="0 0 0" xyz="0 -0.06 0.07"/>
      <inertia ixx="0.0136666666667" ixy="0" ixz="0" iyy="0.003" iyz="0" izz="0.0118666666667"/>
    </inertial>
    <visual>
      <origin rpy="0 0 0" xyz="0 0 0.0"/>
      <geometry>
        <mesh filename="package://lwr_description/meshes/lwr/link_4.STL"/>
      </geometry>
      <material name="Orange"/>
    </visual>
    <!--
      <collision>
        <origin xyz="0 0 0.2" rpy="0 ${M_PI} 0"/>
        <geometry>
          <mesh filename="package://lwr_description/meshes/lwr/convex/arm_segment_b_convex.stl"/>
        </geometry>
      </collision>
-->
    <collision>
      <origin rpy="0 0 0" xyz="0 0 0.2"/>
      <geometry>
        <sphere radius="0.07"/>
      </geometry>
    </collision>
    <collision>
      <origin rpy="0 0 0" xyz="0 -0.06 0.0"/>
      <geometry>
        <sphere radius="0.07"/>
      </geometry>
    </collision>
    <collision>
      <origin rpy="-0.291 0 0" xyz="0 -0.03 0.1"/>
      <geometry>
        <cylinder length="0.208" radius="0.07"/>
      </geometry>
    </collision>
  </link>
  <gazebo reference="left_arm_4_link">
    <gravity>false</gravity>
  </gazebo>
  <transmission name="left_arm_3_trans" type="SimpleTransmission">
    <actuator name="left_arm_3_motor"/>
    <joint name="left_arm_3_joint"/>
    <mechanicalReduction>1.0</mechanicalReduction>
  </transmission>
  <joint name="left_arm_4_joint" type="revolute">
    <origin rpy="0 0 0" xyz="0 0 0.20"/>
    <axis xyz="0 0 1"/>
    <limit effort="204" lower="-2.96705972839" upper="2.96705972839" velocity="0.0226892802759"/>
    <safety_controller k_position="30" k_velocity="30" soft_lower_limit="-2.93215314335" soft_upper_limit="2.93215314335"/>
    <dynamics damping="1.0"/>
    <parent link="left_arm_4_link"/>
    <child link="left_arm_5_link"/>
  </joint>
  <link name="left_arm_5_link">
    <inertial>
      <mass value="2.0"/>
      <origin rpy="0 0 0" xyz="0 0 0.124"/>
      <inertia ixx="0.0126506666667" ixy="0" ixz="0" iyy="0.003" iyz="0" izz="0.0108506666667"/>
    </inertial>
    <visual>
      <origin rpy="0 0 0" xyz="0 0 -0.008"/>
      <geometry name="left_arm_5_geom">
        <mesh filename="package://lwr_description/meshes/lwr/link_5.STL"/>
      </geometry>
      <material name="Orange"/>
    </visual>
    <!--
      <collision>
        <origin xyz="0 0 0" rpy="0 0 0"/>
        <geometry>
          <mesh filename="package://lwr_description/meshes/lwr/convex/arm_segment_last_convex.stl"/>
        </geometry>
      </collision>
-->
    <collision>
      <origin rpy="0 0 0" xyz="0 0 0.0"/>
      <geometry>
        <sphere radius="0.07"/>
      </geometry>
    </collision>
    <collision>
      <origin rpy="0 0 0" xyz="0 -0.04 0.19"/>
      <geometry>
        <sphere radius="0.07"/>
      </geometry>
    </collision>
    <collision>
      <origin rpy="0.207 0 0" xyz="0 -0.02 0.095"/>
      <geometry>
        <cylinder length="0.198" radius="0.07"/>
      </geometry>
    </collision>
  </link>
  <gazebo reference="left_arm_5_link">
    <gravity>false</gravity>
  </gazebo>
  <transmission name="left_arm_4_trans" type="SimpleTransmission">
    <actuator name="left_arm_4_motor"/>
    <joint name="left_arm_4_joint"/>
    <mechanicalReduction>1.0</mechanicalReduction>
  </transmission>
  <joint name="left_arm_5_joint" type="revolute">
    <origin rpy="0 0 0" xyz="0 0 0.19"/>
    <axis xyz="0 1 0"/>
    <limit effort="306" lower="-2.09439510239" upper="2.09439510239" velocity="0.0314159265359"/>
    <safety_controller k_position="30" k_velocity="30" soft_lower_limit="-2.05948851735" soft_upper_limit="2.05948851735"/>
    <dynamics damping="1.0"/>
    <parent link="left_arm_5_link"/>
    <child link="left_arm_6_link"/>
  </joint>
  <link name="left_arm_6_link">
    <inertial>
      <mass value="0.2"/>
      <origin rpy="0 0 0" xyz="0 0 0.0625"/>
      <inertia ixx="0.000520833333333" ixy="0" ixz="0" iyy="0.000520833333333" iyz="0" izz="0.000520833333333"/>
    </inertial>
    <visual>
      <origin rpy="0 0 0" xyz="0 0 0"/>
      <geometry>
        <mesh filename="package://lwr_description/meshes/lwr/link_6.STL"/>
      </geometry>
      <material name="Grey"/>
    </visual>
    <collision>
      <origin rpy="0 0 0" xyz="0 0 0"/>
      <geometry>
        <mesh filename="package://lwr_description/meshes/lwr/convex/arm_wrist_convex.stl"/>
      </geometry>
    </collision>
  </link>
  <gazebo reference="left_arm_6_link">
    <gravity>false</gravity>
  </gazebo>
  <transmission name="left_arm_5_trans" type="SimpleTransmission">
    <actuator name="left_arm_5_motor"/>
    <joint name="left_arm_5_joint"/>
    <mechanicalReduction>1.0</mechanicalReduction>
  </transmission>
  <joint name="left_arm_6_joint" type="revolute">
    <origin rpy="0 0 3.14159265359" xyz="0 0 0.078"/>
    <axis xyz="0 0 1"/>
    <limit effort="204" lower="-2.96705972839" upper="2.96705972839" velocity="0.0314159265359"/>
    <safety_controller k_position="30" k_velocity="30" soft_lower_limit="-2.93215314335" soft_upper_limit="2.93215314335"/>
    <dynamics damping="1.0"/>
    <parent link="left_arm_6_link"/>
    <child link="left_arm_7_link"/>
  </joint>
  <link name="left_arm_7_link">
    <inertial>
      <mass value="0.2"/>
      <origin xyz="0 0 0"/>
      <inertia ixx="0.0333333333333" ixy="0" ixz="0" iyy="0.0333333333333" iyz="0" izz="0.0333333333333"/>
    </inertial>
    <visual>
      <origin rpy="0 0 0" xyz="0 0 0"/>
      <geometry>
        <mesh filename="package://lwr_description/meshes/lwr/link_7.STL"/>
      </geometry>
      <material name="DarkGrey"/>
    </visual>
    <collision>
      <origin rpy="0 0 0.785398163397" xyz="0 0 0"/>
      <geometry>
        <cylinder length="0.05" radius="0.04"/>
      </geometry>
    </collision>
  </link>
  <gazebo reference="left_arm_7_link">
    <gravity>false</gravity>
  </gazebo>
  <transmission name="left_arm_6_trans" type="SimpleTransmission">
    <actuator name="left_arm_6_motor"/>
    <joint name="left_arm_6_joint"/>
    <mechanicalReduction>1.0</mechanicalReduction>
  </transmission>
  <joint name="world_right_arm_base_joint" type="fixed">
    <origin rpy="-2.0628 0.7628 -3.1287" xyz="-0.4962 0.5992 0.6335"/>
    <parent link="world_link"/>
    <child link="calib_right_arm_base_link"/>
  </joint>
  <link name="calib_right_arm_base_link"/>
  <joint name="calib_right_arm_base_joint" type="fixed">
    <origin rpy="0 0 3.14159265359" xyz="0 0 0"/>
    <parent link="calib_right_arm_base_link"/>
    <child link="right_arm_base_link"/>
  </joint>
  <link name="right_arm_base_link">
    <inertial>
      <mass value="2.0"/>
      <origin xyz="0 0 0.055"/>
      <inertia ixx="0.00381666666667" ixy="0" ixz="0" iyy="0.0036" iyz="0" izz="0.00381666666667"/>
    </inertial>
    <visual>
      <origin rpy="0 0 0" xyz="0 0 0"/>
      <geometry>
        <mesh filename="package://lwr_description/meshes/lwr/base.STL"/>
      </geometry>
      <material name="Orange"/>
    </visual>
    <collision>
      <origin rpy="0 0 3.14159265359" xyz="0 0 0.055"/>
      <geometry>
        <!--          <mesh filename="package://lwr_description/meshes/lwr/convex/arm_base_convex.stl"/> -->
        <cylinder length="0.11" radius="0.07"/>
      </geometry>
    </collision>
  </link>
  <joint name="right_arm_0_joint" type="revolute">
    <origin rpy="0 0 0" xyz="0 0 0.11"/>
    <axis xyz="0 0 1"/>
    <limit effort="204" lower="-2.96705972839" upper="2.96705972839" velocity="0.0191986217719"/>
    <safety_controller k_position="30" k_velocity="30" soft_lower_limit="-2.93215314335" soft_upper_limit="2.93215314335"/>
    <dynamics damping="1.0"/>
    <parent link="right_arm_base_link"/>
    <child link="right_arm_1_link"/>
  </joint>
  <link name="right_arm_1_link">
    <inertial>
      <mass value="2.0"/>
      <origin rpy="0 0 0" xyz="0 -0.06 0.130"/>
      <inertia ixx="0.0136666666667" ixy="0" ixz="0" iyy="0.003" iyz="0" izz="0.0118666666667"/>
    </inertial>
    <visual>
      <origin rpy="0 0 0" xyz="0 0 -0.008"/>
      <geometry>
        <mesh filename="package://lwr_description/meshes/lwr/link_1.STL"/>
      </geometry>
      <material name="Orange"/>
    </visual>
    <!--
      <collision>
        <origin xyz="0 0 0" rpy="0 0 0"/>
        <geometry>
          <mesh filename="package://lwr_description/meshes/lwr/convex/arm_segment_a_convex.stl"/>
        </geometry>
      </collision>
 -->
    <collision>
      <origin rpy="0 0 0" xyz="0 0 0.0"/>
      <geometry>
        <sphere radius="0.07"/>
      </geometry>
    </collision>
    <collision>
      <origin rpy="0 0 0" xyz="0 -0.06 0.2"/>
      <geometry>
        <sphere radius="0.07"/>
      </geometry>
    </collision>
    <collision>
      <origin rpy="0.291 0 0" xyz="0 -0.03 0.1"/>
      <geometry>
        <cylinder length="0.208" radius="0.07"/>
      </geometry>
    </collision>
  </link>
  <gazebo reference="right_arm_1_link">
    <gravity>false</gravity>
  </gazebo>
  <transmission name="right_arm_0_trans" type="SimpleTransmission">
    <actuator name="right_arm_0_motor"/>
    <joint name="right_arm_0_joint"/>
    <mechanicalReduction>1.0</mechanicalReduction>
  </transmission>
  <joint name="right_arm_1_joint" type="revolute">
    <origin rpy="0 0 0" xyz="0 0 0.2005"/>
    <axis xyz="0 1 0"/>
    <limit effort="306" lower="-2.09439510239" upper="2.09439510239" velocity="0.0191986217719"/>
    <safety_controller k_position="30" k_velocity="30" soft_lower_limit="-2.05948851735" soft_upper_limit="2.05948851735"/>
    <dynamics damping="1.0" friction="10"/>
    <parent link="right_arm_1_link"/>
    <child link="right_arm_2_link"/>
  </joint>
  <link name="right_arm_2_link">
    <inertial>
      <mass value="2.0"/>
      <origin rpy="0 0 0" xyz="0 0.06 0.07"/>
      <inertia ixx="0.0136666666667" ixy="0" ixz="0" iyy="0.003" iyz="0" izz="0.0118666666667"/>
    </inertial>
    <visual>
      <origin rpy="0 0 0" xyz="0 0 0.0"/>
      <geometry>
        <mesh filename="package://lwr_description/meshes/lwr/link_2.STL"/>
      </geometry>
      <material name="Orange"/>
    </visual>
    <!--
      <collision>
        <origin xyz="0 0 0.2" rpy="${M_PI} 0 0"/>
        <geometry>
          <mesh filename="package://lwr_description/meshes/lwr/convex/arm_segment_b_convex.stl"/>
        </geometry>
      </collision>
-->
    <collision>
      <origin rpy="0 0 0" xyz="0 0 0.2"/>
      <geometry>
        <sphere radius="0.07"/>
      </geometry>
    </collision>
    <collision>
      <origin rpy="0 0 0" xyz="0 0.06 0.0"/>
      <geometry>
        <sphere radius="0.07"/>
      </geometry>
    </collision>
    <collision>
      <origin rpy="0.291 0 0" xyz="0 0.03 0.1"/>
      <geometry>
        <cylinder length="0.208" radius="0.07"/>
      </geometry>
    </collision>
  </link>
  <gazebo reference="right_arm_2_link">
    <gravity>false</gravity>
  </gazebo>
  <transmission name="right_arm_1_trans" type="SimpleTransmission">
    <actuator name="right_arm_1_motor"/>
    <joint name="right_arm_1_joint"/>
    <mechanicalReduction>1.0</mechanicalReduction>
  </transmission>
  <joint name="right_arm_2_joint" type="revolute">
    <origin rpy="0 0 0" xyz="0 0 0.20"/>
    <axis xyz="0 0 1"/>
    <limit effort="204" lower="-2.96705972839" upper="2.96705972839" velocity="0.0226892802759"/>
    <safety_controller k_position="30" k_velocity="30" soft_lower_limit="-2.93215314335" soft_upper_limit="2.93215314335"/>
    <dynamics damping="1.0"/>
    <parent link="right_arm_2_link"/>
    <child link="right_arm_3_link"/>
  </joint>
  <link name="right_arm_3_link">
    <inertial>
      <mass value="2.0"/>
      <origin rpy="0 0 0" xyz="0 0.06 0.130"/>
      <inertia ixx="0.0136666666667" ixy="0" ixz="0" iyy="0.003" iyz="0" izz="0.0118666666667"/>
    </inertial>
    <visual>
      <origin rpy="0 0 0" xyz="0 0 -0.008"/>
      <geometry>
        <mesh filename="package://lwr_description/meshes/lwr/link_3.STL"/>
      </geometry>
      <material name="Orange"/>
    </visual>
    <!--
      <collision>
        <origin xyz="0 0 0" rpy="0 0 ${M_PI}"/>
        <geometry>
          <mesh filename="package://lwr_description/meshes/lwr/convex/arm_segment_a_convex.stl"/>
        </geometry>
      </collision>
-->
    <collision>
      <origin rpy="0 0 0" xyz="0 0 0.0"/>
      <geometry>
        <sphere radius="0.07"/>
      </geometry>
    </collision>
    <collision>
      <origin rpy="0 0 0" xyz="0 0.06 0.2"/>
      <geometry>
        <sphere radius="0.07"/>
      </geometry>
    </collision>
    <collision>
      <origin rpy="-0.291 0 0" xyz="0 0.03 0.1"/>
      <geometry>
        <cylinder length="0.208" radius="0.07"/>
      </geometry>
    </collision>
  </link>
  <gazebo reference="right_arm_3_link">
    <gravity>false</gravity>
  </gazebo>
  <transmission name="right_arm_2_trans" type="SimpleTransmission">
    <actuator name="right_arm_2_motor"/>
    <joint name="right_arm_2_joint"/>
    <mechanicalReduction>1.0</mechanicalReduction>
  </transmission>
  <joint name="right_arm_3_joint" type="revolute">
    <origin rpy="0 0 0" xyz="0 0 0.20"/>
    <axis xyz="0 -1 0"/>
    <limit effort="306" lower="-2.09439510239" upper="2.09439510239" velocity="0.0226892802759"/>
    <safety_controller k_position="30" k_velocity="30" soft_lower_limit="-2.05948851735" soft_upper_limit="2.05948851735"/>
    <dynamics damping="1.0"/>
    <parent link="right_arm_3_link"/>
    <child link="right_arm_4_link"/>
  </joint>
  <link name="right_arm_4_link">
    <inertial>
      <mass value="2.0"/>
      <origin rpy="0 0 0" xyz="0 -0.06 0.07"/>
      <inertia ixx="0.0136666666667" ixy="0" ixz="0" iyy="0.003" iyz="0" izz="0.0118666666667"/>
    </inertial>
    <visual>
      <origin rpy="0 0 0" xyz="0 0 0.0"/>
      <geometry>
        <mesh filename="package://lwr_description/meshes/lwr/link_4.STL"/>
      </geometry>
      <material name="Orange"/>
    </visual>
    <!--
      <collision>
        <origin xyz="0 0 0.2" rpy="0 ${M_PI} 0"/>
        <geometry>
          <mesh filename="package://lwr_description/meshes/lwr/convex/arm_segment_b_convex.stl"/>
        </geometry>
      </collision>
-->
    <collision>
      <origin rpy="0 0 0" xyz="0 0 0.2"/>
      <geometry>
        <sphere radius="0.07"/>
      </geometry>
    </collision>
    <collision>
      <origin rpy="0 0 0" xyz="0 -0.06 0.0"/>
      <geometry>
        <sphere radius="0.07"/>
      </geometry>
    </collision>
    <collision>
      <origin rpy="-0.291 0 0" xyz="0 -0.03 0.1"/>
      <geometry>
        <cylinder length="0.208" radius="0.07"/>
      </geometry>
    </collision>
  </link>
  <gazebo reference="right_arm_4_link">
    <gravity>false</gravity>
  </gazebo>
  <transmission name="right_arm_3_trans" type="SimpleTransmission">
    <actuator name="right_arm_3_motor"/>
    <joint name="right_arm_3_joint"/>
    <mechanicalReduction>1.0</mechanicalReduction>
  </transmission>
  <joint name="right_arm_4_joint" type="revolute">
    <origin rpy="0 0 0" xyz="0 0 0.20"/>
    <axis xyz="0 0 1"/>
    <limit effort="204" lower="-2.96705972839" upper="2.96705972839" velocity="0.0226892802759"/>
    <safety_controller k_position="30" k_velocity="30" soft_lower_limit="-2.93215314335" soft_upper_limit="2.93215314335"/>
    <dynamics damping="1.0"/>
    <parent link="right_arm_4_link"/>
    <child link="right_arm_5_link"/>
  </joint>
  <link name="right_arm_5_link">
    <inertial>
      <mass value="2.0"/>
      <origin rpy="0 0 0" xyz="0 0 0.124"/>
      <inertia ixx="0.0126506666667" ixy="0" ixz="0" iyy="0.003" iyz="0" izz="0.0108506666667"/>
    </inertial>
    <visual>
      <origin rpy="0 0 0" xyz="0 0 -0.008"/>
      <geometry name="right_arm_5_geom">
        <mesh filename="package://lwr_description/meshes/lwr/link_5.STL"/>
      </geometry>
      <material name="Orange"/>
    </visual>
    <!--
      <collision>
        <origin xyz="0 0 0" rpy="0 0 0"/>
        <geometry>
          <mesh filename="package://lwr_description/meshes/lwr/convex/arm_segment_last_convex.stl"/>
        </geometry>
      </collision>
-->
    <collision>
      <origin rpy="0 0 0" xyz="0 0 0.0"/>
      <geometry>
        <sphere radius="0.07"/>
      </geometry>
    </collision>
    <collision>
      <origin rpy="0 0 0" xyz="0 -0.04 0.19"/>
      <geometry>
        <sphere radius="0.07"/>
      </geometry>
    </collision>
    <collision>
      <origin rpy="0.207 0 0" xyz="0 -0.02 0.095"/>
      <geometry>
        <cylinder length="0.198" radius="0.07"/>
      </geometry>
    </collision>
  </link>
  <gazebo reference="right_arm_5_link">
    <gravity>false</gravity>
  </gazebo>
  <transmission name="right_arm_4_trans" type="SimpleTransmission">
    <actuator name="right_arm_4_motor"/>
    <joint name="right_arm_4_joint"/>
    <mechanicalReduction>1.0</mechanicalReduction>
  </transmission>
  <joint name="right_arm_5_joint" type="revolute">
    <origin rpy="0 0 0" xyz="0 0 0.19"/>
    <axis xyz="0 1 0"/>
    <limit effort="306" lower="-2.09439510239" upper="2.09439510239" velocity="0.0314159265359"/>
    <safety_controller k_position="30" k_velocity="30" soft_lower_limit="-2.05948851735" soft_upper_limit="2.05948851735"/>
    <dynamics damping="1.0"/>
    <parent link="right_arm_5_link"/>
    <child link="right_arm_6_link"/>
  </joint>
  <link name="right_arm_6_link">
    <inertial>
      <mass value="0.2"/>
      <origin rpy="0 0 0" xyz="0 0 0.0625"/>
      <inertia ixx="0.000520833333333" ixy="0" ixz="0" iyy="0.000520833333333" iyz="0" izz="0.000520833333333"/>
    </inertial>
    <visual>
      <origin rpy="0 0 0" xyz="0 0 0"/>
      <geometry>
        <mesh filename="package://lwr_description/meshes/lwr/link_6.STL"/>
      </geometry>
      <material name="Grey"/>
    </visual>
    <collision>
      <origin rpy="0 0 0" xyz="0 0 0"/>
      <geometry>
        <mesh filename="package://lwr_description/meshes/lwr/convex/arm_wrist_convex.stl"/>
      </geometry>
    </collision>
  </link>
  <gazebo reference="right_arm_6_link">
    <gravity>false</gravity>
  </gazebo>
  <transmission name="right_arm_5_trans" type="SimpleTransmission">
    <actuator name="right_arm_5_motor"/>
    <joint name="right_arm_5_joint"/>
    <mechanicalReduction>1.0</mechanicalReduction>
  </transmission>
  <joint name="right_arm_6_joint" type="revolute">
    <origin rpy="0 0 3.14159265359" xyz="0 0 0.078"/>
    <axis xyz="0 0 1"/>
    <limit effort="204" lower="-2.96705972839" upper="2.96705972839" velocity="0.0314159265359"/>
    <safety_controller k_position="30" k_velocity="30" soft_lower_limit="-2.93215314335" soft_upper_limit="2.93215314335"/>
    <dynamics damping="1.0"/>
    <parent link="right_arm_6_link"/>
    <child link="right_arm_7_link"/>
  </joint>
  <link name="right_arm_7_link">
    <inertial>
      <mass value="0.2"/>
      <origin xyz="0 0 0"/>
      <inertia ixx="0.0333333333333" ixy="0" ixz="0" iyy="0.0333333333333" iyz="0" izz="0.0333333333333"/>
    </inertial>
    <visual>
      <origin rpy="0 0 0" xyz="0 0 0"/>
      <geometry>
        <mesh filename="package://lwr_description/meshes/lwr/link_7.STL"/>
      </geometry>
      <material name="DarkGrey"/>
    </visual>
    <collision>
      <origin rpy="0 0 -0.785398163397" xyz="0 0 0"/>
      <geometry>
        <cylinder length="0.05" radius="0.04"/>
      </geometry>
    </collision>
  </link>
  <gazebo reference="right_arm_7_link">
    <gravity>false</gravity>
  </gazebo>
  <transmission name="right_arm_6_trans" type="SimpleTransmission">
    <actuator name="right_arm_6_motor"/>
    <joint name="right_arm_6_joint"/>
    <mechanicalReduction>1.0</mechanicalReduction>
  </transmission>
  <!-- joint between arm_7_link and the connector ring -->
  <joint name="left_sdh_connector_joint" type="fixed">
    <origin xyz="0 0 0"/>
    <parent link="left_arm_7_link"/>
    <child link="left_sdh_connector_link"/>
  </joint>
  <!-- connector ring added to adjust distance to arm connector -->
  <link name="left_sdh_connector_link">
    <visual>
      <origin rpy="0 0 0" xyz="0 0 0.0084"/>
      <geometry>
        <cylinder length="0.0168" radius="0.02735"/>
      </geometry>
      <material name="DarkGrey"/>
    </visual>
    <collision>
      <origin rpy="0 0 0" xyz="0 0 0.0084"/>
      <geometry>
        <cylinder length="0.0168" radius="0.02735"/>
      </geometry>
    </collision>
  </link>
  <joint name="left_sdh_palm_joint" type="fixed">
    <origin rpy="0 0 -1.57079632679" xyz="0 0 0.0168"/>
    <parent link="left_sdh_connector_link"/>
    <child link="left_sdh_palm_link"/>
  </joint>
  <link name="left_sdh_palm_link">
    <inertial>
      <origin rpy="0 0 0" xyz="0 0 0"/>
      <mass value="1"/>
      <inertia ixx="0.01" ixy="0" ixz="0" iyy="0.01" iyz="0" izz="0.01"/>
    </inertial>
    <visual>
      <origin rpy="0 0 0" xyz="0 0 0"/>
      <geometry>
        <mesh filename="package://schunk_description/meshes/sdh/palm.stl"/>
      </geometry>
      <material name="Schunk/LightGrey"/>
    </visual>
    <collision>
      <origin rpy="0 0 0" xyz="0 0 0"/>
      <geometry>
        <mesh filename="package://schunk_description/meshes/sdh/palm.stl"/>
      </geometry>
    </collision>
  </link>
  <joint name="left_sdh_grasp_joint" type="fixed">
    <origin rpy="0 0 0" xyz="0 0 0.15"/>
    <parent link="left_sdh_palm_link"/>
    <child link="left_sdh_grasp_link"/>
  </joint>
  <link name="left_sdh_grasp_link"/>
  <joint name="left_sdh_tip_joint" type="fixed">
    <origin rpy="0 0 0" xyz="0 0 0.22"/>
    <parent link="left_sdh_palm_link"/>
    <child link="left_sdh_tip_link"/>
  </joint>
  <link name="left_sdh_tip_link"/>
  <joint name="left_sdh_knuckle_joint" type="revolute">
    <origin rpy="0 0 3.14159265" xyz="0.01905 0.033 0.0745"/>
    <parent link="left_sdh_palm_link"/>
    <child link="left_sdh_finger_11_link"/>
    <axis xyz="0 0 1"/>
    <dynamics damping="1"/>
    <limit effort="100" lower="0" upper="1.570796327" velocity="5"/>
  </joint>
  <link name="left_sdh_finger_11_link">
    <inertial>
      <origin rpy="0 0 0" xyz="0 0 0"/>
      <mass value="0.1"/>
      <inertia ixx="0.01" ixy="0" ixz="0" iyy="0.01" iyz="0" izz="0.01"/>
    </inertial>
    <visual>
      <origin rpy="0 0 0" xyz="0 0 0"/>
      <geometry>
        <mesh filename="package://schunk_description/meshes/sdh/knuckle.stl"/>
      </geometry>
      <material name="Schunk/LightGrey"/>
    </visual>
    <collision>
      <origin rpy="0 0 0" xyz="0 0 0"/>
      <geometry>
        <mesh filename="package://schunk_description/meshes/sdh/knuckle.stl"/>
      </geometry>
    </collision>
  </link>
  <joint name="left_sdh_finger_12_joint" type="revolute">
    <origin rpy="0 0 0" xyz="0 0 0.0165"/>
    <parent link="left_sdh_finger_11_link"/>
    <child link="left_sdh_finger_12_link"/>
    <axis xyz="0 1 0"/>
    <dynamics damping="1"/>
    <limit effort="100" lower="-1.570796327" upper="1.570796327" velocity="5"/>
  </joint>
  <link name="left_sdh_finger_12_link">
    <inertial>
      <origin rpy="0 0 0" xyz="0 0 0"/>
      <mass value="0.1"/>
      <inertia ixx="0.01" ixy="0" ixz="0" iyy="0.01" iyz="0" izz="0.01"/>
    </inertial>
    <visual>
      <origin rpy="0 0 0" xyz="0 0 0"/>
      <geometry>
        <mesh filename="package://schunk_description/meshes/sdh/finger.stl"/>
      </geometry>
      <material name="Schunk/LightGrey"/>
    </visual>
    <collision>
      <origin rpy="0 0 0" xyz="0 0 0"/>
      <geometry>
        <mesh filename="package://schunk_description/meshes/sdh/finger.stl"/>
      </geometry>
    </collision>
  </link>
  <joint name="left_sdh_finger_13_joint" type="revolute">
    <origin rpy="0 0 0" xyz="0 0 0.0865"/>
    <parent link="left_sdh_finger_12_link"/>
    <child link="left_sdh_finger_13_link"/>
    <axis xyz="0 1 0"/>
    <dynamics damping="1"/>
    <limit effort="100" lower="-1.570796327" upper="1.570796327" velocity="5"/>
  </joint>
  <link name="left_sdh_finger_13_link">
    <inertial>
      <origin rpy="0 0 0" xyz="0 0 0"/>
      <mass value="0.1"/>
      <inertia ixx="0.01" ixy="0" ixz="0" iyy="0.01" iyz="0" izz="0.01"/>
    </inertial>
    <visual>
      <origin rpy="0 0 0" xyz="0 0 0"/>
      <geometry>
        <mesh filename="package://schunk_description/meshes/sdh/finger_tip.stl"/>
      </geometry>
      <material name="Schunk/LightGrey"/>
    </visual>
    <collision>
      <origin rpy="0 0 0" xyz="0 0 0"/>
      <geometry>
        <mesh filename="package://schunk_description/meshes/sdh/finger_tip.stl"/>
      </geometry>
    </collision>
  </link>
  <joint name="left_sdh_finger_21_joint" type="revolute">
    <mimic joint="left_sdh_knuckle_joint" multiplier="1" offset="0"/>
    <origin rpy="0 0 3.14159265" xyz="0.01905 -0.033 0.0745"/>
    <parent link="left_sdh_palm_link"/>
    <child link="left_sdh_finger_21_link"/>
    <axis xyz="0 0 -1"/>
    <dynamics damping="1"/>
    <limit effort="100" lower="0" upper="1.570796327" velocity="5"/>
  </joint>
  <link name="left_sdh_finger_21_link">
    <inertial>
      <origin rpy="0 0 0" xyz="0 0 0"/>
      <mass value="0.1"/>
      <inertia ixx="0.01" ixy="0" ixz="0" iyy="0.01" iyz="0" izz="0.01"/>
    </inertial>
    <visual>
      <origin rpy="0 0 0" xyz="0 0 0"/>
      <geometry>
        <mesh filename="package://schunk_description/meshes/sdh/knuckle.stl"/>
      </geometry>
      <material name="Schunk/LightGrey"/>
    </visual>
    <collision>
      <origin rpy="0 0 0" xyz="0 0 0"/>
      <geometry>
        <mesh filename="package://schunk_description/meshes/sdh/knuckle.stl"/>
      </geometry>
    </collision>
  </link>
  <joint name="left_sdh_finger_22_joint" type="revolute">
    <origin rpy="0 0 0" xyz="0 0 0.0165"/>
    <parent link="left_sdh_finger_21_link"/>
    <child link="left_sdh_finger_22_link"/>
    <axis xyz="0 1 0"/>
    <dynamics damping="1"/>
    <limit effort="100" lower="-1.570796327" upper="1.570796327" velocity="5"/>
  </joint>
  <link name="left_sdh_finger_22_link">
    <inertial>
      <origin rpy="0 0 0" xyz="0 0 0"/>
      <mass value="0.1"/>
      <inertia ixx="0.01" ixy="0" ixz="0" iyy="0.01" iyz="0" izz="0.01"/>
    </inertial>
    <visual>
      <origin rpy="0 0 0" xyz="0 0 0"/>
      <geometry>
        <mesh filename="package://schunk_description/meshes/sdh/finger.stl"/>
      </geometry>
      <material name="Schunk/LightGrey"/>
    </visual>
    <collision>
      <origin rpy="0 0 0" xyz="0 0 0"/>
      <geometry>
        <mesh filename="package://schunk_description/meshes/sdh/finger.stl"/>
      </geometry>
    </collision>
  </link>
  <joint name="left_sdh_finger_23_joint" type="revolute">
    <origin rpy="0 0 0" xyz="0 0 0.0865"/>
    <parent link="left_sdh_finger_22_link"/>
    <child link="left_sdh_finger_23_link"/>
    <axis xyz="0 1 0"/>
    <dynamics damping="1"/>
    <limit effort="100" lower="-1.570796327" upper="1.570796327" velocity="5"/>
  </joint>
  <link name="left_sdh_finger_23_link">
    <inertial>
      <origin rpy="0 0 0" xyz="0 0 0"/>
      <mass value="0.1"/>
      <inertia ixx="0.01" ixy="0" ixz="0" iyy="0.01" iyz="0" izz="0.01"/>
    </inertial>
    <visual>
      <origin rpy="0 0 0" xyz="0 0 0"/>
      <geometry>
        <mesh filename="package://schunk_description/meshes/sdh/finger_tip.stl"/>
      </geometry>
      <material name="Schunk/LightGrey"/>
    </visual>
    <collision>
      <origin rpy="0 0 0" xyz="0 0 0"/>
      <geometry>
        <mesh filename="package://schunk_description/meshes/sdh/finger_tip.stl"/>
      </geometry>
    </collision>
  </link>
  <joint name="left_sdh_thumb_1_joint" type="fixed">
    <origin rpy="0 0 0" xyz="-0.03811 0 0.0745 "/>
    <parent link="left_sdh_palm_link"/>
    <child link="left_sdh_thumb_1_link"/>
  </joint>
  <link name="left_sdh_thumb_1_link">
    <inertial>
      <origin rpy="0 0 0" xyz="0 0 0"/>
      <mass value="0.1"/>
      <inertia ixx="0.01" ixy="0" ixz="0" iyy="0.01" iyz="0" izz="0.01"/>
    </inertial>
    <visual>
      <origin rpy="0 0 0" xyz="0 0 0"/>
      <geometry>
        <mesh filename="package://schunk_description/meshes/sdh/knuckle.stl"/>
      </geometry>
      <material name="Schunk/LightGrey"/>
    </visual>
    <collision>
      <origin rpy="0 0 0" xyz="0 0 0"/>
      <geometry>
        <mesh filename="package://schunk_description/meshes/sdh/knuckle.stl"/>
      </geometry>
    </collision>
  </link>
  <joint name="left_sdh_thumb_2_joint" type="revolute">
    <origin rpy="0 0 0" xyz="0 0 0.0165"/>
    <parent link="left_sdh_thumb_1_link"/>
    <child link="left_sdh_thumb_2_link"/>
    <axis xyz="0 1 0"/>
    <dynamics damping="1"/>
    <limit effort="100" lower="-1.570796327" upper="1.570796327" velocity="5"/>
  </joint>
  <link name="left_sdh_thumb_2_link">
    <inertial>
      <origin rpy="0 0 0" xyz="0 0 0"/>
      <mass value="0.1"/>
      <inertia ixx="0.01" ixy="0" ixz="0" iyy="0.01" iyz="0" izz="0.01"/>
    </inertial>
    <visual>
      <origin rpy="0 0 0" xyz="0 0 0"/>
      <geometry>
        <mesh filename="package://schunk_description/meshes/sdh/finger.stl"/>
      </geometry>
      <material name="Schunk/LightGrey"/>
    </visual>
    <collision>
      <origin rpy="0 0 0" xyz="0 0 0"/>
      <geometry>
        <mesh filename="package://schunk_description/meshes/sdh/finger.stl"/>
      </geometry>
    </collision>
  </link>
  <joint name="left_sdh_thumb_3_joint" type="revolute">
    <origin rpy="0 0 0" xyz="0 0 0.0865"/>
    <parent link="left_sdh_thumb_2_link"/>
    <child link="left_sdh_thumb_3_link"/>
    <axis xyz="0 1 0"/>
    <dynamics damping="1"/>
    <limit effort="100" lower="-1.570796327" upper="1.570796327" velocity="5"/>
  </joint>
  <link name="left_sdh_thumb_3_link">
    <inertial>
      <origin rpy="0 0 0" xyz="0 0 0"/>
      <mass value="0.1"/>
      <inertia ixx="0.01" ixy="0" ixz="0" iyy="0.01" iyz="0" izz="0.01"/>
    </inertial>
    <visual>
      <origin rpy="0 0 0" xyz="0 0 0"/>
      <geometry>
        <mesh filename="package://schunk_description/meshes/sdh/finger_tip.stl"/>
      </geometry>
      <material name="Schunk/LightGrey"/>
    </visual>
    <collision>
      <origin rpy="0 0 0" xyz="0 0 0"/>
      <geometry>
        <mesh filename="package://schunk_description/meshes/sdh/finger_tip.stl"/>
      </geometry>
    </collision>
  </link>
  <gazebo reference="left_sdh_palm_link">
    <material>Schunk/LightGrey</material>
    <turnGravityOff>false</turnGravityOff>
  </gazebo>
  <gazebo reference="left_sdh_finger_11_link">
    <material>Schunk/LightGrey</material>
    <turnGravityOff>false</turnGravityOff>
  </gazebo>
  <gazebo reference="left_sdh_finger_12_link">
    <selfCollide>true</selfCollide>
    <sensor name="left_sdh_finger_12_contact_sensor" type="contact">
      <always_on>true</always_on>
      <update_rate>100</update_rate>
      <contact>
        <collision>left_sdh_finger_12_link_geom</collision>
      </contact>
      <plugin filename="libgazebo_ros_bumper.so" name="left_sdh_finger_12_gazebo_ros_bumper_controller">
        <alwaysOn>true</alwaysOn>
        <updateRate>100.0</updateRate>
        <frameName>left_sdh_finger_12_link</frameName>
        <bumperTopicName>left_sdh_finger_12_bumper</bumperTopicName>
      </plugin>
    </sensor>
    <material>Schunk/LightGrey</material>
    <turnGravityOff>false</turnGravityOff>
  </gazebo>
  <gazebo reference="left_sdh_finger_13_link">
    <selfCollide>true</selfCollide>
    <sensor name="left_sdh_finger_13_contact_sensor" type="contact">
      <always_on>true</always_on>
      <update_rate>100</update_rate>
      <contact>
        <collision>left_sdh_finger_13_link_geom</collision>
      </contact>
      <plugin filename="libgazebo_ros_bumper.so" name="left_sdh_finger_13_gazebo_ros_bumper_controller">
        <alwaysOn>true</alwaysOn>
        <updateRate>100.0</updateRate>
        <frameName>left_sdh_finger_13_link</frameName>
        <bumperTopicName>left_sdh_finger_13_bumper</bumperTopicName>
      </plugin>
    </sensor>
    <material>Schunk/LightGrey</material>
  </gazebo>
  <gazebo reference="left_sdh_finger_21_link">
    <material>Schunk/LightGrey</material>
    <turnGravityOff>false</turnGravityOff>
  </gazebo>
  <gazebo reference="left_sdh_finger_22_link">
    <selfCollide>true</selfCollide>
    <sensor name="left_sdh_finger_22_contact_sensor" type="contact">
      <always_on>true</always_on>
      <update_rate>100</update_rate>
      <contact>
        <collision>left_sdh_finger_22_link_geom</collision>
      </contact>
      <plugin filename="libgazebo_ros_bumper.so" name="left_sdh_finger_22_gazebo_ros_bumper_controller">
        <alwaysOn>true</alwaysOn>
        <updateRate>100.0</updateRate>
        <frameName>left_sdh_finger_22_link</frameName>
        <bumperTopicName>left_sdh_finger_22_bumper</bumperTopicName>
      </plugin>
    </sensor>
    <material>Schunk/LightGrey</material>
    <turnGravityOff>false</turnGravityOff>
  </gazebo>
  <gazebo reference="left_sdh_finger_23_link">
    <selfCollide>true</selfCollide>
    <sensor name="left_sdh_finger_23_contact_sensor" type="contact">
      <always_on>true</always_on>
      <update_rate>100</update_rate>
      <contact>
        <collision>left_sdh_finger_23_link_geom</collision>
      </contact>
      <plugin filename="libgazebo_ros_bumper.so" name="left_sdh_finger_23_gazebo_ros_bumper_controller">
        <alwaysOn>true</alwaysOn>
        <updateRate>100.0</updateRate>
        <frameName>left_sdh_finger_23_link</frameName>
        <bumperTopicName>left_sdh_finger_23_bumper</bumperTopicName>
      </plugin>
    </sensor>
    <material>Schunk/LightGrey</material>
  </gazebo>
  <gazebo reference="left_sdh_thumb_1_link">
    <material>Schunk/LightGrey</material>
    <turnGravityOff>false</turnGravityOff>
  </gazebo>
  <gazebo reference="left_sdh_thumb_2_link">
    <selfCollide>true</selfCollide>
    <sensor name="left_sdh_thumb_2_contact_sensor" type="contact">
      <always_on>true</always_on>
      <update_rate>100</update_rate>
      <contact>
        <collision>left_sdh_thumb_2_link_geom</collision>
      </contact>
      <plugin filename="libgazebo_ros_bumper.so" name="left_sdh_thumb_2_gazebo_ros_bumper_controller">
        <alwaysOn>true</alwaysOn>
        <updateRate>100.0</updateRate>
        <frameName>left_sdh_thumb_2_link</frameName>
        <bumperTopicName>left_sdh_thumb_2_bumper</bumperTopicName>
      </plugin>
    </sensor>
    <material>Schunk/LightGrey</material>
    <turnGravityOff>false</turnGravityOff>
  </gazebo>
  <gazebo reference="left_sdh_thumb_3_link">
    <selfCollide>true</selfCollide>
    <sensor name="left_sdh_thumb_3_contact_sensor" type="contact">
      <always_on>true</always_on>
      <update_rate>100</update_rate>
      <contact>
        <collision>left_sdh_thumb_3_link_geom</collision>
      </contact>
      <plugin filename="libgazebo_ros_bumper.so" name="left_sdh_thumb_3_gazebo_ros_bumper_controller">
        <alwaysOn>true</alwaysOn>
        <updateRate>100.0</updateRate>
        <frameName>left_sdh_thumb_3_link</frameName>
        <bumperTopicName>left_sdh_thumb_3_bumper</bumperTopicName>
      </plugin>
    </sensor>
    <material>Schunk/LightGrey</material>
  </gazebo>
  <transmission name="left_sdh_knuckle_trans" type="pr2_mechanism_model/SimpleTransmission">
    <actuator name="left_sdh_knuckle_motor"/>
    <joint name="left_sdh_finger_21_joint"/>
    <mechanicalReduction>1</mechanicalReduction>
  </transmission>
  <transmission name="left_sdh_knuckle_trans" type="pr2_mechanism_model/SimpleTransmission">
    <actuator name="left_sdh_knuckle_motor"/>
    <joint name="left_sdh_knuckle_joint"/>
    <mechanicalReduction>1</mechanicalReduction>
  </transmission>
  <transmission name="left_sdh_finger_12_trans" type="pr2_mechanism_model/SimpleTransmission">
    <actuator name="left_sdh_finger_12_motor"/>
    <joint name="left_sdh_finger_12_joint"/>
    <mechanicalReduction>1</mechanicalReduction>
  </transmission>
  <transmission name="left_sdh_finger_13_trans" type="pr2_mechanism_model/SimpleTransmission">
    <actuator name="left_sdh_finger_13_motor"/>
    <joint name="left_sdh_finger_13_joint"/>
    <mechanicalReduction>1</mechanicalReduction>
  </transmission>
  <transmission name="left_sdh_finger_22_trans" type="pr2_mechanism_model/SimpleTransmission">
    <actuator name="left_sdh_finger_22_motor"/>
    <joint name="left_sdh_finger_22_joint"/>
    <mechanicalReduction>1</mechanicalReduction>
  </transmission>
  <transmission name="left_sdh_finger_23_trans" type="pr2_mechanism_model/SimpleTransmission">
    <actuator name="left_sdh_finger_23_motor"/>
    <joint name="left_sdh_finger_23_joint"/>
    <mechanicalReduction>1</mechanicalReduction>
  </transmission>
  <transmission name="left_sdh_thumb_2_trans" type="pr2_mechanism_model/SimpleTransmission">
    <actuator name="left_sdh_thumb_2_motor"/>
    <joint name="left_sdh_thumb_2_joint"/>
    <mechanicalReduction>1</mechanicalReduction>
  </transmission>
  <transmission name="left_sdh_thumb_3_trans" type="pr2_mechanism_model/SimpleTransmission">
    <actuator name="left_sdh_thumb_3_motor"/>
    <joint name="left_sdh_thumb_3_joint"/>
    <mechanicalReduction>1</mechanicalReduction>
  </transmission>
  <!-- This connector can be a macro inside the hand package descrption -->
  <!-- joint between arm_7_link and the connector ring -->
  <joint name="right_sdh_connector_joint" type="fixed">
    <origin xyz="0 0 0"/>
    <parent link="right_arm_7_link"/>
    <child link="right_sdh_connector_link"/>
  </joint>
  <!-- connector ring added to adjust distance to arm connector -->
  <link name="right_sdh_connector_link">
    <visual>
      <origin rpy="0 0 0" xyz="0 0 0.0084"/>
      <geometry>
        <cylinder length="0.0168" radius="0.02735"/>
      </geometry>
      <material name="DarkGrey"/>
    </visual>
    <collision>
      <origin rpy="0 0 0" xyz="0 0 0.0084"/>
      <geometry>
        <cylinder length="0.0168" radius="0.02735"/>
      </geometry>
    </collision>
  </link>
  <joint name="right_sdh_palm_joint" type="fixed">
    <origin rpy="0 0 1.57079632679" xyz="0 0 0.0168"/>
    <parent link="right_sdh_connector_link"/>
    <child link="right_sdh_palm_link"/>
  </joint>
  <link name="right_sdh_palm_link">
    <inertial>
      <origin rpy="0 0 0" xyz="0 0 0"/>
      <mass value="1"/>
      <inertia ixx="0.01" ixy="0" ixz="0" iyy="0.01" iyz="0" izz="0.01"/>
    </inertial>
    <visual>
      <origin rpy="0 0 0" xyz="0 0 0"/>
      <geometry>
        <mesh filename="package://schunk_description/meshes/sdh/palm.stl"/>
      </geometry>
      <material name="Schunk/LightGrey"/>
    </visual>
    <collision>
      <origin rpy="0 0 0" xyz="0 0 0"/>
      <geometry>
        <mesh filename="package://schunk_description/meshes/sdh/palm.stl"/>
      </geometry>
    </collision>
  </link>
  <joint name="right_sdh_grasp_joint" type="fixed">
    <origin rpy="0 0 0" xyz="0 0 0.15"/>
    <parent link="right_sdh_palm_link"/>
    <child link="right_sdh_grasp_link"/>
  </joint>
  <link name="right_sdh_grasp_link"/>
  <joint name="right_sdh_tip_joint" type="fixed">
    <origin rpy="0 0 0" xyz="0 0 0.22"/>
    <parent link="right_sdh_palm_link"/>
    <child link="right_sdh_tip_link"/>
  </joint>
  <link name="right_sdh_tip_link"/>
  <joint name="right_sdh_knuckle_joint" type="revolute">
    <origin rpy="0 0 3.14159265" xyz="0.01905 0.033 0.0745"/>
    <parent link="right_sdh_palm_link"/>
    <child link="right_sdh_finger_11_link"/>
    <axis xyz="0 0 1"/>
    <dynamics damping="1"/>
    <limit effort="100" lower="0" upper="1.570796327" velocity="5"/>
  </joint>
  <link name="right_sdh_finger_11_link">
    <inertial>
      <origin rpy="0 0 0" xyz="0 0 0"/>
      <mass value="0.1"/>
      <inertia ixx="0.01" ixy="0" ixz="0" iyy="0.01" iyz="0" izz="0.01"/>
    </inertial>
    <visual>
      <origin rpy="0 0 0" xyz="0 0 0"/>
      <geometry>
        <mesh filename="package://schunk_description/meshes/sdh/knuckle.stl"/>
      </geometry>
      <material name="Schunk/LightGrey"/>
    </visual>
    <collision>
      <origin rpy="0 0 0" xyz="0 0 0"/>
      <geometry>
        <mesh filename="package://schunk_description/meshes/sdh/knuckle.stl"/>
      </geometry>
    </collision>
  </link>
  <joint name="right_sdh_finger_12_joint" type="revolute">
    <origin rpy="0 0 0" xyz="0 0 0.0165"/>
    <parent link="right_sdh_finger_11_link"/>
    <child link="right_sdh_finger_12_link"/>
    <axis xyz="0 1 0"/>
    <dynamics damping="1"/>
    <limit effort="100" lower="-1.570796327" upper="1.570796327" velocity="5"/>
  </joint>
  <link name="right_sdh_finger_12_link">
    <inertial>
      <origin rpy="0 0 0" xyz="0 0 0"/>
      <mass value="0.1"/>
      <inertia ixx="0.01" ixy="0" ixz="0" iyy="0.01" iyz="0" izz="0.01"/>
    </inertial>
    <visual>
      <origin rpy="0 0 0" xyz="0 0 0"/>
      <geometry>
        <mesh filename="package://schunk_description/meshes/sdh/finger.stl"/>
      </geometry>
      <material name="Schunk/LightGrey"/>
    </visual>
    <collision>
      <origin rpy="0 0 0" xyz="0 0 0"/>
      <geometry>
        <mesh filename="package://schunk_description/meshes/sdh/finger.stl"/>
      </geometry>
    </collision>
  </link>
  <joint name="right_sdh_finger_13_joint" type="revolute">
    <origin rpy="0 0 0" xyz="0 0 0.0865"/>
    <parent link="right_sdh_finger_12_link"/>
    <child link="right_sdh_finger_13_link"/>
    <axis xyz="0 1 0"/>
    <dynamics damping="1"/>
    <limit effort="100" lower="-1.570796327" upper="1.570796327" velocity="5"/>
  </joint>
  <link name="right_sdh_finger_13_link">
    <inertial>
      <origin rpy="0 0 0" xyz="0 0 0"/>
      <mass value="0.1"/>
      <inertia ixx="0.01" ixy="0" ixz="0" iyy="0.01" iyz="0" izz="0.01"/>
    </inertial>
    <visual>
      <origin rpy="0 0 0" xyz="0 0 0"/>
      <geometry>
        <mesh filename="package://schunk_description/meshes/sdh/finger_tip.stl"/>
      </geometry>
      <material name="Schunk/LightGrey"/>
    </visual>
    <collision>
      <origin rpy="0 0 0" xyz="0 0 0"/>
      <geometry>
        <mesh filename="package://schunk_description/meshes/sdh/finger_tip.stl"/>
      </geometry>
    </collision>
  </link>
  <joint name="right_sdh_finger_21_joint" type="revolute">
    <mimic joint="right_sdh_knuckle_joint" multiplier="1" offset="0"/>
    <origin rpy="0 0 3.14159265" xyz="0.01905 -0.033 0.0745"/>
    <parent link="right_sdh_palm_link"/>
    <child link="right_sdh_finger_21_link"/>
    <axis xyz="0 0 -1"/>
    <dynamics damping="1"/>
    <limit effort="100" lower="0" upper="1.570796327" velocity="5"/>
  </joint>
  <link name="right_sdh_finger_21_link">
    <inertial>
      <origin rpy="0 0 0" xyz="0 0 0"/>
      <mass value="0.1"/>
      <inertia ixx="0.01" ixy="0" ixz="0" iyy="0.01" iyz="0" izz="0.01"/>
    </inertial>
    <visual>
      <origin rpy="0 0 0" xyz="0 0 0"/>
      <geometry>
        <mesh filename="package://schunk_description/meshes/sdh/knuckle.stl"/>
      </geometry>
      <material name="Schunk/LightGrey"/>
    </visual>
    <collision>
      <origin rpy="0 0 0" xyz="0 0 0"/>
      <geometry>
        <mesh filename="package://schunk_description/meshes/sdh/knuckle.stl"/>
      </geometry>
    </collision>
  </link>
  <joint name="right_sdh_finger_22_joint" type="revolute">
    <origin rpy="0 0 0" xyz="0 0 0.0165"/>
    <parent link="right_sdh_finger_21_link"/>
    <child link="right_sdh_finger_22_link"/>
    <axis xyz="0 1 0"/>
    <dynamics damping="1"/>
    <limit effort="100" lower="-1.570796327" upper="1.570796327" velocity="5"/>
  </joint>
  <link name="right_sdh_finger_22_link">
    <inertial>
      <origin rpy="0 0 0" xyz="0 0 0"/>
      <mass value="0.1"/>
      <inertia ixx="0.01" ixy="0" ixz="0" iyy="0.01" iyz="0" izz="0.01"/>
    </inertial>
    <visual>
      <origin rpy="0 0 0" xyz="0 0 0"/>
      <geometry>
        <mesh filename="package://schunk_description/meshes/sdh/finger.stl"/>
      </geometry>
      <material name="Schunk/LightGrey"/>
    </visual>
    <collision>
      <origin rpy="0 0 0" xyz="0 0 0"/>
      <geometry>
        <mesh filename="package://schunk_description/meshes/sdh/finger.stl"/>
      </geometry>
    </collision>
  </link>
  <joint name="right_sdh_finger_23_joint" type="revolute">
    <origin rpy="0 0 0" xyz="0 0 0.0865"/>
    <parent link="right_sdh_finger_22_link"/>
    <child link="right_sdh_finger_23_link"/>
    <axis xyz="0 1 0"/>
    <dynamics damping="1"/>
    <limit effort="100" lower="-1.570796327" upper="1.570796327" velocity="5"/>
  </joint>
  <link name="right_sdh_finger_23_link">
    <inertial>
      <origin rpy="0 0 0" xyz="0 0 0"/>
      <mass value="0.1"/>
      <inertia ixx="0.01" ixy="0" ixz="0" iyy="0.01" iyz="0" izz="0.01"/>
    </inertial>
    <visual>
      <origin rpy="0 0 0" xyz="0 0 0"/>
      <geometry>
        <mesh filename="package://schunk_description/meshes/sdh/finger_tip.stl"/>
      </geometry>
      <material name="Schunk/LightGrey"/>
    </visual>
    <collision>
      <origin rpy="0 0 0" xyz="0 0 0"/>
      <geometry>
        <mesh filename="package://schunk_description/meshes/sdh/finger_tip.stl"/>
      </geometry>
    </collision>
  </link>
  <joint name="right_sdh_thumb_1_joint" type="fixed">
    <origin rpy="0 0 0" xyz="-0.03811 0 0.0745 "/>
    <parent link="right_sdh_palm_link"/>
    <child link="right_sdh_thumb_1_link"/>
  </joint>
  <link name="right_sdh_thumb_1_link">
    <inertial>
      <origin rpy="0 0 0" xyz="0 0 0"/>
      <mass value="0.1"/>
      <inertia ixx="0.01" ixy="0" ixz="0" iyy="0.01" iyz="0" izz="0.01"/>
    </inertial>
    <visual>
      <origin rpy="0 0 0" xyz="0 0 0"/>
      <geometry>
        <mesh filename="package://schunk_description/meshes/sdh/knuckle.stl"/>
      </geometry>
      <material name="Schunk/LightGrey"/>
    </visual>
    <collision>
      <origin rpy="0 0 0" xyz="0 0 0"/>
      <geometry>
        <mesh filename="package://schunk_description/meshes/sdh/knuckle.stl"/>
      </geometry>
    </collision>
  </link>
  <joint name="right_sdh_thumb_2_joint" type="revolute">
    <origin rpy="0 0 0" xyz="0 0 0.0165"/>
    <parent link="right_sdh_thumb_1_link"/>
    <child link="right_sdh_thumb_2_link"/>
    <axis xyz="0 1 0"/>
    <dynamics damping="1"/>
    <limit effort="100" lower="-1.570796327" upper="1.570796327" velocity="5"/>
  </joint>
  <link name="right_sdh_thumb_2_link">
    <inertial>
      <origin rpy="0 0 0" xyz="0 0 0"/>
      <mass value="0.1"/>
      <inertia ixx="0.01" ixy="0" ixz="0" iyy="0.01" iyz="0" izz="0.01"/>
    </inertial>
    <visual>
      <origin rpy="0 0 0" xyz="0 0 0"/>
      <geometry>
        <mesh filename="package://schunk_description/meshes/sdh/finger.stl"/>
      </geometry>
      <material name="Schunk/LightGrey"/>
    </visual>
    <collision>
      <origin rpy="0 0 0" xyz="0 0 0"/>
      <geometry>
        <mesh filename="package://schunk_description/meshes/sdh/finger.stl"/>
      </geometry>
    </collision>
  </link>
  <joint name="right_sdh_thumb_3_joint" type="revolute">
    <origin rpy="0 0 0" xyz="0 0 0.0865"/>
    <parent link="right_sdh_thumb_2_link"/>
    <child link="right_sdh_thumb_3_link"/>
    <axis xyz="0 1 0"/>
    <dynamics damping="1"/>
    <limit effort="100" lower="-1.570796327" upper="1.570796327" velocity="5"/>
  </joint>
  <link name="right_sdh_thumb_3_link">
    <inertial>
      <origin rpy="0 0 0" xyz="0 0 0"/>
      <mass value="0.1"/>
      <inertia ixx="0.01" ixy="0" ixz="0" iyy="0.01" iyz="0" izz="0.01"/>
    </inertial>
    <visual>
      <origin rpy="0 0 0" xyz="0 0 0"/>
      <geometry>
        <mesh filename="package://schunk_description/meshes/sdh/finger_tip.stl"/>
      </geometry>
      <material name="Schunk/LightGrey"/>
    </visual>
    <collision>
      <origin rpy="0 0 0" xyz="0 0 0"/>
      <geometry>
        <mesh filename="package://schunk_description/meshes/sdh/finger_tip.stl"/>
      </geometry>
    </collision>
  </link>
  <gazebo reference="right_sdh_palm_link">
    <material>Schunk/LightGrey</material>
    <turnGravityOff>false</turnGravityOff>
  </gazebo>
  <gazebo reference="right_sdh_finger_11_link">
    <material>Schunk/LightGrey</material>
    <turnGravityOff>false</turnGravityOff>
  </gazebo>
  <gazebo reference="right_sdh_finger_12_link">
    <selfCollide>true</selfCollide>
    <sensor name="right_sdh_finger_12_contact_sensor" type="contact">
      <always_on>true</always_on>
      <update_rate>100</update_rate>
      <contact>
        <collision>right_sdh_finger_12_link_geom</collision>
      </contact>
      <plugin filename="libgazebo_ros_bumper.so" name="right_sdh_finger_12_gazebo_ros_bumper_controller">
        <alwaysOn>true</alwaysOn>
        <updateRate>100.0</updateRate>
        <frameName>right_sdh_finger_12_link</frameName>
        <bumperTopicName>right_sdh_finger_12_bumper</bumperTopicName>
      </plugin>
    </sensor>
    <material>Schunk/LightGrey</material>
    <turnGravityOff>false</turnGravityOff>
  </gazebo>
  <gazebo reference="right_sdh_finger_13_link">
    <selfCollide>true</selfCollide>
    <sensor name="right_sdh_finger_13_contact_sensor" type="contact">
      <always_on>true</always_on>
      <update_rate>100</update_rate>
      <contact>
        <collision>right_sdh_finger_13_link_geom</collision>
      </contact>
      <plugin filename="libgazebo_ros_bumper.so" name="right_sdh_finger_13_gazebo_ros_bumper_controller">
        <alwaysOn>true</alwaysOn>
        <updateRate>100.0</updateRate>
        <frameName>right_sdh_finger_13_link</frameName>
        <bumperTopicName>right_sdh_finger_13_bumper</bumperTopicName>
      </plugin>
    </sensor>
    <material>Schunk/LightGrey</material>
  </gazebo>
  <gazebo reference="right_sdh_finger_21_link">
    <material>Schunk/LightGrey</material>
    <turnGravityOff>false</turnGravityOff>
  </gazebo>
  <gazebo reference="right_sdh_finger_22_link">
    <selfCollide>true</selfCollide>
    <sensor name="right_sdh_finger_22_contact_sensor" type="contact">
      <always_on>true</always_on>
      <update_rate>100</update_rate>
      <contact>
        <collision>right_sdh_finger_22_link_geom</collision>
      </contact>
      <plugin filename="libgazebo_ros_bumper.so" name="right_sdh_finger_22_gazebo_ros_bumper_controller">
        <alwaysOn>true</alwaysOn>
        <updateRate>100.0</updateRate>
        <frameName>right_sdh_finger_22_link</frameName>
        <bumperTopicName>right_sdh_finger_22_bumper</bumperTopicName>
      </plugin>
    </sensor>
    <material>Schunk/LightGrey</material>
    <turnGravityOff>false</turnGravityOff>
  </gazebo>
  <gazebo reference="right_sdh_finger_23_link">
    <selfCollide>true</selfCollide>
    <sensor name="right_sdh_finger_23_contact_sensor" type="contact">
      <always_on>true</always_on>
      <update_rate>100</update_rate>
      <contact>
        <collision>right_sdh_finger_23_link_geom</collision>
      </contact>
      <plugin filename="libgazebo_ros_bumper.so" name="right_sdh_finger_23_gazebo_ros_bumper_controller">
        <alwaysOn>true</alwaysOn>
        <updateRate>100.0</updateRate>
        <frameName>right_sdh_finger_23_link</frameName>
        <bumperTopicName>right_sdh_finger_23_bumper</bumperTopicName>
      </plugin>
    </sensor>
    <material>Schunk/LightGrey</material>
  </gazebo>
  <gazebo reference="right_sdh_thumb_1_link">
    <material>Schunk/LightGrey</material>
    <turnGravityOff>false</turnGravityOff>
  </gazebo>
  <gazebo reference="right_sdh_thumb_2_link">
    <selfCollide>true</selfCollide>
    <sensor name="right_sdh_thumb_2_contact_sensor" type="contact">
      <always_on>true</always_on>
      <update_rate>100</update_rate>
      <contact>
        <collision>right_sdh_thumb_2_link_geom</collision>
      </contact>
      <plugin filename="libgazebo_ros_bumper.so" name="right_sdh_thumb_2_gazebo_ros_bumper_controller">
        <alwaysOn>true</alwaysOn>
        <updateRate>100.0</updateRate>
        <frameName>right_sdh_thumb_2_link</frameName>
        <bumperTopicName>right_sdh_thumb_2_bumper</bumperTopicName>
      </plugin>
    </sensor>
    <material>Schunk/LightGrey</material>
    <turnGravityOff>false</turnGravityOff>
  </gazebo>
  <gazebo reference="right_sdh_thumb_3_link">
    <selfCollide>true</selfCollide>
    <sensor name="right_sdh_thumb_3_contact_sensor" type="contact">
      <always_on>true</always_on>
      <update_rate>100</update_rate>
      <contact>
        <collision>right_sdh_thumb_3_link_geom</collision>
      </contact>
      <plugin filename="libgazebo_ros_bumper.so" name="right_sdh_thumb_3_gazebo_ros_bumper_controller">
        <alwaysOn>true</alwaysOn>
        <updateRate>100.0</updateRate>
        <frameName>right_sdh_thumb_3_link</frameName>
        <bumperTopicName>right_sdh_thumb_3_bumper</bumperTopicName>
      </plugin>
    </sensor>
    <material>Schunk/LightGrey</material>
  </gazebo>
  <transmission name="right_sdh_knuckle_trans" type="pr2_mechanism_model/SimpleTransmission">
    <actuator name="right_sdh_knuckle_motor"/>
    <joint name="right_sdh_finger_21_joint"/>
    <mechanicalReduction>1</mechanicalReduction>
  </transmission>
  <transmission name="right_sdh_knuckle_trans" type="pr2_mechanism_model/SimpleTransmission">
    <actuator name="right_sdh_knuckle_motor"/>
    <joint name="right_sdh_knuckle_joint"/>
    <mechanicalReduction>1</mechanicalReduction>
  </transmission>
  <transmission name="right_sdh_finger_12_trans" type="pr2_mechanism_model/SimpleTransmission">
    <actuator name="right_sdh_finger_12_motor"/>
    <joint name="right_sdh_finger_12_joint"/>
    <mechanicalReduction>1</mechanicalReduction>
  </transmission>
  <transmission name="right_sdh_finger_13_trans" type="pr2_mechanism_model/SimpleTransmission">
    <actuator name="right_sdh_finger_13_motor"/>
    <joint name="right_sdh_finger_13_joint"/>
    <mechanicalReduction>1</mechanicalReduction>
  </transmission>
  <transmission name="right_sdh_finger_22_trans" type="pr2_mechanism_model/SimpleTransmission">
    <actuator name="right_sdh_finger_22_motor"/>
    <joint name="right_sdh_finger_22_joint"/>
    <mechanicalReduction>1</mechanicalReduction>
  </transmission>
  <transmission name="right_sdh_finger_23_trans" type="pr2_mechanism_model/SimpleTransmission">
    <actuator name="right_sdh_finger_23_motor"/>
    <joint name="right_sdh_finger_23_joint"/>
    <mechanicalReduction>1</mechanicalReduction>
  </transmission>
  <transmission name="right_sdh_thumb_2_trans" type="pr2_mechanism_model/SimpleTransmission">
    <actuator name="right_sdh_thumb_2_motor"/>
    <joint name="right_sdh_thumb_2_joint"/>
    <mechanicalReduction>1</mechanicalReduction>
  </transmission>
  <transmission name="right_sdh_thumb_3_trans" type="pr2_mechanism_model/SimpleTransmission">
    <actuator name="right_sdh_thumb_3_motor"/>
    <joint name="right_sdh_thumb_3_joint"/>
    <mechanicalReduction>1</mechanicalReduction>
  </transmission>
  <!-- HEAD -->
  <joint name="world_head_base_joint" type="fixed">
    <origin xyz="-0.4723 0.6767 0.85"/>
    <parent link="world_link"/>
    <child link="calib_head_base_link"/>
  </joint>
  <link name="calib_head_base_link"/>
  <joint name="head_neck_pitch_joint" type="revolute">
    <origin rpy="-1.57079632679 0 0" xyz="0 0 0"/>
    <axis xyz="0 0 1"/>
    <limit effort="204" lower="-0.575958653158" upper="0.575958653158" velocity="3.14159265359"/>
    <safety_controller k_position="30" k_velocity="30" soft_lower_limit="-0.575958653158" soft_upper_limit="0.575958653158"/>
    <dynamics damping="1.0"/>
    <parent link="calib_head_base_link"/>
    <child link="head_head_1_link"/>
  </joint>
  <link name="head_head_1_link">
    <visual>
      <origin rpy="0 0 0" xyz="0 0 0"/>
      <geometry>
        <cylinder length="0.15" radius="0.03"/>
      </geometry>
      <material name="KIT/DarkGrey"/>
    </visual>
    <collision>
      <origin rpy="0 0 0" xyz="0 0 0"/>
      <geometry>
        <cylinder length="0.15" radius="0.03"/>
      </geometry>
    </collision>
  </link>
  <joint name="head_neck_roll_joint" type="revolute">
    <origin rpy="0 1.57079632679 0" xyz="0 0 0"/>
    <axis xyz="0 0 1"/>
    <limit effort="204" lower="-0.488692190558" upper="0.488692190558" velocity="3.14159265359"/>
    <safety_controller k_position="30" k_velocity="30" soft_lower_limit="-0.488692190558" soft_upper_limit="0.488692190558"/>
    <dynamics damping="1.0"/>
    <parent link="head_head_1_link"/>
    <child link="head_head_2_link"/>
  </joint>
  <link name="head_head_2_link">
    <visual>
      <origin rpy="0 0 0" xyz="0 0 0"/>
      <geometry>
        <cylinder length="0.15" radius="0.03"/>
      </geometry>
      <material name="KIT/DarkGrey"/>
    </visual>
    <collision>
      <origin rpy="0 0 0" xyz="0 0 0"/>
      <geometry>
        <cylinder length="0.15" radius="0.03"/>
      </geometry>
    </collision>
  </link>
  <joint name="head_neck_yaw_joint" type="revolute">
    <origin rpy="-1.57079632679 -1.57079632679 0" xyz="0 0 0"/>
    <axis xyz="0 0 1"/>
    <limit effort="204" lower="-1.98967534727" upper="1.98967534727" velocity="3.14159265359"/>
    <safety_controller k_position="30" k_velocity="30" soft_lower_limit="-1.98967534727" soft_upper_limit="1.98967534727"/>
    <dynamics damping="1.0"/>
    <parent link="head_head_2_link"/>
    <child link="head_head_3_link"/>
  </joint>
  <link name="head_head_3_link">
    <visual>
      <origin rpy="0 0 0" xyz="0 0 0"/>
      <geometry>
        <cylinder length="0.15" radius="0.03"/>
      </geometry>
      <material name="KIT/DarkGrey"/>
    </visual>
    <collision>
      <origin rpy="0 0 0" xyz="0 0 0"/>
      <geometry>
        <cylinder length="0.15" radius="0.03"/>
      </geometry>
    </collision>
  </link>
  <joint name="head_head_tilt_joint" type="revolute">
    <origin rpy="1.57079632679 0 0" xyz="0 0 -0.1745"/>
    <axis xyz="0 0 1"/>
    <limit effort="204" lower="-0.698131700798" upper="0.698131700798" velocity="3.14159265359"/>
    <safety_controller k_position="30" k_velocity="30" soft_lower_limit="-0.698131700798" soft_upper_limit="0.698131700798"/>
    <dynamics damping="1.0"/>
    <parent link="head_head_3_link"/>
    <child link="head_head_4_link"/>
  </joint>
  <link name="head_head_4_link">
    <visual>
      <origin rpy="0 0 0" xyz="0 0 0"/>
      <geometry>
        <cylinder length="0.15" radius="0.03"/>
      </geometry>
      <material name="KIT/DarkGrey"/>
    </visual>
    <collision>
      <origin rpy="0 0 0" xyz="0 0 0"/>
      <geometry>
        <cylinder length="0.15" radius="0.03"/>
      </geometry>
    </collision>
  </link>
  <joint name="head_eyes_tilt_joint" type="revolute">
    <origin rpy="0 0 0" xyz="0.1 0 0"/>
    <axis xyz="0 0 1"/>
    <limit effort="204" lower="-0.349065850399" upper="0.349065850399" velocity="3.14159265359"/>
    <safety_controller k_position="30" k_velocity="30" soft_lower_limit="-0.349065850399" soft_upper_limit="0.349065850399"/>
    <dynamics damping="1.0"/>
    <parent link="head_head_4_link"/>
    <child link="head_head_5_link"/>
  </joint>
  <link name="head_head_5_link">
    <visual>
      <origin rpy="0 0 0" xyz="0 0 0"/>
      <geometry>
        <cylinder length="0.03" radius="0.03"/>
      </geometry>
      <material name="KIT/DarkGrey"/>
    </visual>
    <collision>
      <origin rpy="1.57079632679 0 0" xyz="0 0.18 0"/>
      <geometry>
        <cylinder length="0.4" radius="0.15"/>
      </geometry>
    </collision>
  </link>
  <joint name="head_left_eye_joint" type="revolute">
    <origin rpy="1.57079632679 0 0" xyz="0 0 0.0465"/>
    <axis xyz="0 0 1"/>
    <limit effort="204" lower="-0.349065850399" upper="0.349065850399" velocity="3.14159265359"/>
    <safety_controller k_position="30" k_velocity="30" soft_lower_limit="-0.349065850399" soft_upper_limit="0.349065850399"/>
    <dynamics damping="1.0"/>
    <parent link="head_head_5_link"/>
    <child link="head_left_eye_link"/>
  </joint>
  <link name="head_left_eye_link">
    <visual>
      <origin rpy="0 1.57079632679 0" xyz="0.02 0 0"/>
      <geometry>
        <cylinder length="0.02" radius="0.03"/>
      </geometry>
      <material name="KIT/White"/>
    </visual>
    <collision>
      <origin rpy="0 0 0" xyz="0.02 0 0"/>
      <geometry>
        <cylinder length="0.02" radius="0.03"/>
      </geometry>
    </collision>
  </link>
  <joint name="head_right_eye_joint" type="revolute">
    <origin rpy="1.57079632679 0 0" xyz="0 0 -0.0465"/>
    <axis xyz="0 0 1"/>
    <limit effort="204" lower="-0.349065850399" upper="0.349065850399" velocity="3.14159265359"/>
    <safety_controller k_position="30" k_velocity="30" soft_lower_limit="-0.349065850399" soft_upper_limit="0.349065850399"/>
    <dynamics damping="1.0"/>
    <parent link="head_head_5_link"/>
    <child link="head_right_eye_link"/>
  </joint>
  <link name="head_right_eye_link">
    <visual>
      <origin rpy="0 1.57079632679 0" xyz="0.02 0 0"/>
      <geometry>
        <cylinder length="0.02" radius="0.03"/>
      </geometry>
      <material name="KIT/White"/>
    </visual>
    <collision>
      <origin rpy="0 0 0" xyz="0.02 0 0"/>
      <geometry>
        <cylinder length="0.02" radius="0.03"/>
      </geometry>
    </collision>
  </link>
  <!-- Kinect vision sensor -->
  <!-- <link name="camera_link"/>
  <joint name="kinect_visionSensor_joint" type="fixed" >
    <origin xyz="-0.40271 0.66297 0.796599"
      rpy="-1.69854 -0.0579848 -2.43762"/>
    <parent link="world_link" />
    <child link="camera_link" /> 
  </joint> -->
  <!-- simulator-->
  <!-- <joint name="kinect_visionSensor_joint" type="fixed" >
    <origin xyz="-0.4568 0.6891 0.7516"
      rpy="2.2689 0.0 1.5708"/>
    <parent link="world_link" />
    <child link="kinect_visionSensor" />
  </joint> -->
</robot>
